Workbook

Sheet About

Sheet Workflow

Sheet PFD

Sheet PythonUnitOps
A1: UnitClass | B1: PartitioningType | C1: Reference date | D1: Reference currency | E1: Notes
A2: MyDehulling | B2: Overall, Component | C2: 2025 | D2: USD
A3: MyImpactMilling | B3: None | C3: 2004 | D3: NZD
A4: MyCombine | B4: None
A5: MyClarifier | B5: Overall, Component | C5: 2004 | D5: NZD
A6: MyUltrafiltration | B6: MCF, RC | C6: 2004 | D6: NZD
A7: MyDiafiltration | B7: DF, RC | C7: 2004 | D7: NZD
A8: MySprayDryer | B8: Drying | C8: 2026 | D8: NZD
A9: MySplitter | B9: Overall
A10: MyAirClassification | B10: Overall, Component | C10: 2004 | D10: NZD
A11: MyFiltration | B11: Overall, Component
A12: MyWetExtraction | B12: None | C12: 2008 | D12: USD
A13: MyPasteurisation | B13: None | C13: 2004 | D13: NZD
A14: MyReverseOsmosis | B14: MCF, RC | C14: 2004 | D14: NZD
A15: MyCyclone | B15: Overall, Component | C15: 2004 | D15: NZD
A16: MyCooling | B16: None | C16: 2004 | D16: NZD
A17: MyMixingTank | B17: None | C17: 2008 | D17: USD
A18: MyDrumDryer | B18: Drying | C18: 2008 | D18: USD
A19: MyDecanterCentrifuge | B19: Overall, Component | C19: 2004 | D19: NZD
A20: MyHoldingTube | B20: None | C20: 2002 | D20: USD

Sheet fc
A1: https://www.xe.com/currencytables/?from=NZD&date=2004-07-02 | B1: =YEAR(TODAY()) -> 2026 | C1: 1981 | D1: 1982 | E1: 1982 | F1: 1983 | G1: 1984 | H1: 1985 | I1: 1986 | J1: 1987 | K1: 1988 | L1: 1989 | M1: 1990 | N1: 1991 | O1: 1992 | P1: 1993 | Q1: 1994 | R1: 1995 | S1: 1996 | T1: 1997 | U1: 1998 | V1: 1999 | W1: 2000 | X1: 2001 | Y1: 2002 | Z1: 2003 | AA1: 2004 | AB1: 2005 | AC1: 2006 | AD1: 2007 | AE1: 2008 | AF1: 2009 | AG1: 2010 | AH1: 2011 | AI1: 2012 | AJ1: 2013 | AK1: 2014 | AL1: 2015 | AM1: 2016 | AN1: 2017 | AO1: 2018 | AP1: 2019 | AQ1: 2020 | AR1: 2021 | AS1: 2022 | AT1: 2023 | AU1: 2024 | AV1: 2025
A2: USD | B2: =FORECAST(B$1,INDEX(S2:BE2, 1, COUNTA(S2:BE2)-4):INDEX(S2:BE2, 1, COUNTA(S2:BE2)),INDEX($S$1:$BE$1, 1, COUNTA($S$1:$BE$1)-4):INDEX($S$1:$BE$1, 1, COUNTA($S$1:$BE$1))) -> 1.729514 | E2: 1.302423 | F2: 1.532567 | G2: 1.506478 | S2: 1.4602614 | T2: 1.4743096 | U2: 1.9481019 | V2: 1.8748946 | W2: 2.1321962 | X2: 2.469142 | Y2: 2.1243971 | Z2: 2.0501294 | AA2: 1.5460334 | AB2: 1.46305 | AC2: 1.64065 | AD2: 1.2779897 | AE2: 1.3133595 | AF2: 1.5902381 | AG2: 1.4119312 | AH2: 1.3043772 | AI2: 1.2215979 | AJ2: 1.1939389 | AK2: 1.1534053 | AL2: 1.3408423 | AM2: 1.4501745 | AN2: 1.4274499 | AO2: 1.3806302 | AP2: 1.6015821 | AQ2: 1.5012462 | AR2: 1.4410587 | AS2: 1.5763308 | AT2: 1.6067924 | AU2: 1.6572522 | AV2: 1.6419825
A3: EUR | B3: =FORECAST(B$1,INDEX(S3:BE3, 1, COUNTA(S3:BE3)-4):INDEX(S3:BE3, 1, COUNTA(S3:BE3)),INDEX($S$1:$BE$1, 1, COUNTA($S$1:$BE$1)-4):INDEX($S$1:$BE$1, 1, COUNTA($S$1:$BE$1))) -> 1.95686 | S3: #N/A | T3: #N/A | U3: #N/A | V3: 1.9206651 | W3: 2.0298507 | X3: 2.0879052 | Y3: 2.0929892 | Z3: 2.0152917 | AA3: 1.9027802 | AB3: 1.7494425 | AC3: 2.0965032 | AD3: 1.7413752 | AE3: 2.0837026 | AF3: 2.2288263 | AG3: 1.9172353 | AH3: 1.8535631 | AI3: 1.6301012 | AJ3: 1.534909 | AK3: 1.5922028 | AL3: 1.4436432 | AM3: 1.6502044 | AN3: 1.5209585 | AO3: 1.7010998 | AP3: 1.7510663 | AQ3: 1.7858355 | AR3: 1.6711454 | AS3: 1.6185502 | AT3: 1.7229279 | AU3: 1.7928259 | AV3: 1.9327183
A4: GBP | B4: =FORECAST(B$1,INDEX(S4:BE4, 1, COUNTA(S4:BE4)-4):INDEX(S4:BE4, 1, COUNTA(S4:BE4)),INDEX($S$1:$BE$1, 1, COUNTA($S$1:$BE$1)-4):INDEX($S$1:$BE$1, 1, COUNTA($S$1:$BE$1))) -> 2.2602739 | E4: =E2/0.560214 -> 2.3248669 | F4: =F2/0.675341 -> 2.2693232 | G4: =G2/0.692699 -> 2.1747945 | S4: 2.2761354 | T4: 2.4566474 | U4: 3.2259092 | V4: 2.9602599 | W4: 3.2324094 | X4: 3.4977738 | Y4: 3.3362844 | Z4: 3.1354555 | AA4: 2.829505 | AB4: 2.5875685 | AC4: 3.0330733 | AD4: 2.5762655 | AE4: 2.6165925 | AF4: 2.6070832 | AG4: 2.1589885 | AH4: 2.1035517 | AI4: 1.9561446 | AJ4: 1.8182947 | AK4: 1.919046 | AL4: 1.9880679 | AM4: 2.0599034 | AN4: 1.7905931 | AO4: 1.9340349 | AP4: 1.9608316 | AQ4: 1.9727422 | AR4: 1.9551362 | AS4: 1.9349268 | AT4: 1.9517247 | AU4: 2.0861394 | AV4: 2.2530079
A5: INR | B5: =FORECAST(B$1,INDEX(S5:BE5, 1, COUNTA(S5:BE5)-4):INDEX(S5:BE5, 1, COUNTA(S5:BE5)),INDEX($S$1:$BE$1, 1, COUNTA($S$1:$BE$1)-4):INDEX($S$1:$BE$1, 1, COUNTA($S$1:$BE$1))) -> 0.019383695 | S5: 0.042020137 | T5: 0.041243845 | U5: 0.04588532 | V5: 0.043210293 | W5: 0.047753553 | X5: 0.052389378 | Y5: 0.043955945 | Z5: 0.042007524 | AA5: 0.033774623 | AB5: 0.033606294 | AC5: 0.03575959 | AD5: 0.031617755 | AE5: 0.030422968 | AF5: 0.032965636 | AG5: 0.031519782 | AH5: 0.029341513 | AI5: 0.024011161 | AJ5: 0.021993704 | AK5: 0.019263695 | AL5: 0.021582808 | AM5: 0.021857209 | AN5: 0.02202627 | AO5: 0.021193702 | AP5: 0.022517702 | AQ5: 0.020064876 | AR5: 0.019426296 | AS5: 0.019966144 | AT5: 0.01952656 | AU5: 0.019845854 | AV5: 0.019153236
A6: AUD | B6: =FORECAST(B$1,INDEX(S6:BE6, 1, COUNTA(S6:BE6)-4):INDEX(S6:BE6, 1, COUNTA(S6:BE6)),INDEX($S$1:$BE$1, 1, COUNTA($S$1:$BE$1)-4):INDEX($S$1:$BE$1, 1, COUNTA($S$1:$BE$1))) -> 1.0963295 | E6: =E2/0.95057 -> 1.3701495 | F6: =F2/1.156738 -> 1.3249042 | G6: =G2/1.068148 -> 1.4103645 | S6: 1.1434233 | T6: 1.108435 | U6: 1.1924608 | V6: 1.2560977 | W6: 1.271855 | X6: 1.2611425 | Y6: 1.1514901 | Z6: 1.1525748 | AA6: 1.1018511 | AB6: 1.1001617 | AC6: 1.2178221 | AD6: 1.0983596 | AE6: 1.2650396 | AF6: 1.2635552 | AG6: 1.3009979 | AH6: 1.3544692 | AI6: 1.2639873 | AJ6: 1.2441207 | AK6: 1.0669946 | AL6: 1.0208187 | AM6: 1.1124207 | AN6: 1.0892156 | AO6: 1.0604228 | AP6: 1.0732723 | AQ6: 1.0830494 | AR6: 1.0475789 | AS6: 1.1085582 | AT6: 1.0706008 | AU6: 1.0975694 | AV6: 1.0791401
A7: CAD | B7: =FORECAST(B$1,INDEX(S7:BE7, 1, COUNTA(S7:BE7)-4):INDEX(S7:BE7, 1, COUNTA(S7:BE7)),INDEX($S$1:$BE$1, 1, COUNTA($S$1:$BE$1)-4):INDEX($S$1:$BE$1, 1, COUNTA($S$1:$BE$1))) -> 1.2283516 | S7: 1.0711225 | T7: 1.0704346 | U7: 1.3273162 | V7: 1.280713 | W7: 1.4403811 | X7: 1.6296247 | Y7: 1.339726 | Z7: 1.3435035 | AA7: 1.1669751 | AB7: 1.1781213 | AC7: 1.468498 | AD7: 1.210957 | AE7: 1.2967015 | AF7: 1.3709488 | AG7: 1.4014241 | AH7: 1.3542335 | AI7: 1.2233717 | AJ7: 1.1740537 | AK7: 1.0459297 | AL7: 1.0627571 | AM7: 1.111491 | AN7: 1.0715826 | AO7: 1.0708129 | AP7: 1.2101142 | AQ7: 1.1325686 | AR7: 1.1380993 | AS7: 1.2280045 | AT7: 1.174834 | AU7: 1.2139318 | AV7: 1.2055738
A8: SGD | B8: =FORECAST(B$1,INDEX(S8:BE8, 1, COUNTA(S8:BE8)-4):INDEX(S8:BE8, 1, COUNTA(S8:BE8)),INDEX($S$1:$BE$1, 1, COUNTA($S$1:$BE$1)-4):INDEX($S$1:$BE$1, 1, COUNTA($S$1:$BE$1))) -> 1.3444073 | S8: 1.0347044 | T8: 1.0312567 | U8: 1.1418901 | V8: 1.1058536 | W8: 1.234267 | X8: 1.3551079 | Y8: 1.189932 | Z8: 1.1576377 | AA8: 0.90300623 | AB8: 0.8633601 | AC8: 1.0365819 | AD8: 0.83906041 | AE8: 0.96776327 | AF8: 1.095809 | AG8: 1.0109357 | AH8: 1.0346263 | AI8: 0.97137234 | AJ8: 0.96247469 | AK8: 0.91618139 | AL8: 0.98315968 | AM8: 1.0749534 | AN8: 1.02176 | AO8: 1.0528619 | AP8: 1.1559953 | AQ8: 1.0975982 | AR8: 1.0633676 | AS8: 1.1453873 | AT8: 1.1950031 | AU8: 1.2255059 | AV8: 1.2906743
A9: CHF | B9: =FORECAST(B$1,INDEX(S9:BE9, 1, COUNTA(S9:BE9)-4):INDEX(S9:BE9, 1, COUNTA(S9:BE9)),INDEX($S$1:$BE$1, 1, COUNTA($S$1:$BE$1)-4):INDEX($S$1:$BE$1, 1, COUNTA($S$1:$BE$1))) -> 2.1342037 | S9: 1.167952 | T9: 1.0010704 | U9: 1.2693125 | V9: 1.1961937 | W9: 1.3059326 | X9: 1.3717362 | Y9: 1.4359352 | Z9: 1.3759239 | AA9: 1.2538096 | AB9: 1.1283742 | AC9: 1.3411673 | AD9: 1.0550912 | AE9: 1.294018 | AF9: 1.4673726 | AG9: 1.3380699 | AH9: 1.4111457 | AI9: 1.3543213 | AJ9: 1.2619681 | AK9: 1.3068652 | AL9: 1.3864412 | AM9: 1.5120282 | AN9: 1.4226839 | AO9: 1.4475065 | AP9: 1.6123949 | AQ9: 1.6580872 | AR9: 1.549675 | AS9: 1.6612247 | AT9: 1.7589667 | AU9: 1.8278083 | AV9: 2.0681234
A10: MYR | B10: =FORECAST(B$1,INDEX(S10:BE10, 1, COUNTA(S10:BE10)-4):INDEX(S10:BE10, 1, COUNTA(S10:BE10)),INDEX($S$1:$BE$1, 1, COUNTA($S$1:$BE$1)-4):INDEX($S$1:$BE$1, 1, COUNTA($S$1:$BE$1))) -> 0.3855428 | S10: 0.58526135 | T10: 0.58413616 | U10: 0.46495885 | V10: 0.49339332 | W10: 0.56125195 | X10: 0.64977422 | Y10: 0.55920075 | Z10: 0.53950823 | AA10: 0.40685089 | AB10: 0.38578473 | AC10: 0.44646575 | AD10: 0.37211234 | AE10: 0.40111919 | AF10: 0.45167532 | AG10: 0.43524391 | AH10: 0.43112782 | AI10: 0.39827137 | AJ10: 0.38591967 | AK10: 0.35339496 | AL10: 0.36429584 | AM10: 0.37404253 | AN10: 0.3224418 | AO10: 0.35724395 | AP10: 0.38198565 | AQ10: 0.35789047 | AR10: 0.34468464 | AS10: 0.35399664 | AT10: 0.35795804 | AU10: 0.35082215 | AV10: 0.38976705
A11: JPY | B11: =FORECAST(B$1,INDEX(S11:BE11, 1, COUNTA(S11:BE11)-4):INDEX(S11:BE11, 1, COUNTA(S11:BE11)),INDEX($S$1:$BE$1, 1, COUNTA($S$1:$BE$1)-4):INDEX($S$1:$BE$1, 1, COUNTA($S$1:$BE$1))) -> 0.010407641 | S11: 0.013260497 | T11: 0.012877328 | U11: 0.013750995 | V11: 0.015483399 | W11: 0.020134053 | X11: 0.01986968 | Y11: 0.017312967 | Z11: 0.017052954 | AA11: 0.014236693 | AB11: 0.013089242 | AC11: 0.014338213 | AD11: 0.010447973 | AE11: 0.012405691 | AF11: 0.016581968 | AG11: 0.015046689 | AH11: 0.015516411 | AI11: 0.014750925 | AJ11: 0.012755595 | AK11: 0.011142068 | AL11: 0.011209681 | AM11: 0.012937628 | AN11: 0.012816609 | AO11: 0.012988191 | AP11: 0.014869677 | AQ11: 0.014235031 | AR11: 0.012986184 | AS11: 0.011962164 | AT11: 0.01196317 | AU11: 0.010589067 | AV11: 0.011388954
A12: CNY | B12: =FORECAST(B$1,INDEX(S12:BE12, 1, COUNTA(S12:BE12)-4):INDEX(S12:BE12, 1, COUNTA(S12:BE12)),INDEX($S$1:$BE$1, 1, COUNTA($S$1:$BE$1)-4):INDEX($S$1:$BE$1, 1, COUNTA($S$1:$BE$1))) -> 0.23198266 | S12: 0.17544987 | T12: 0.17779919 | U12: 0.23533316 | V12: 0.22647758 | W12: 0.25787912 | X12: 0.29831364 | Y12: 0.25670289 | Z12: 0.24768991 | AA12: 0.18668068 | AB12: 0.1767714 | AC12: 0.20527369 | AD12: 0.16803493 | AE12: 0.19161943 | AF12: 0.23275637 | AG12: 0.20680364 | AH12: 0.19917805 | AI12: 0.1939968 | AJ12: 0.19255175 | AK12: 0.18580415 | AL12: 0.2164343 | AM12: 0.22403036 | AN12: 0.20718607 | AO12: 0.2200436 | AP12: 0.22404539 | AQ12: 0.21645058 | AR12: 0.2235055 | AS12: 0.23290319 | AT12: 0.23379456 | AU12: 0.22910311 | AV12: 0.22920588
A13: NZD | B13: =FORECAST(B$1,INDEX(S13:BE13, 1, COUNTA(S13:BE13)-4):INDEX(S13:BE13, 1, COUNTA(S13:BE13)),INDEX($S$1:$BE$1, 1, COUNTA($S$1:$BE$1)-4):INDEX($S$1:$BE$1, 1, COUNTA($S$1:$BE$1))) -> 1 | S13: 1 | T13: 1 | U13: 1 | V13: 1 | W13: 1 | X13: 1 | Y13: 1 | Z13: 1 | AA13: 1 | AB13: 1 | AC13: 1 | AD13: 1 | AE13: 1 | AF13: 1 | AG13: 1 | AH13: 1 | AI13: 1 | AJ13: 1 | AK13: 1 | AL13: 1 | AM13: 1 | AN13: 1 | AO13: 1 | AP13: 1 | AQ13: 1 | AR13: 1 | AS13: 1 | AT13: 1 | AU13: 1 | AV13: 1
A14: THB | B14: =FORECAST(B$1,INDEX(S14:BE14, 1, COUNTA(S14:BE14)-4):INDEX(S14:BE14, 1, COUNTA(S14:BE14)),INDEX($S$1:$BE$1, 1, COUNTA($S$1:$BE$1)-4):INDEX($S$1:$BE$1, 1, COUNTA($S$1:$BE$1))) -> 0.050886919 | S14: 0.05751928 | T14: 0.050845643 | U14: 0.046164056 | V14: 0.050823926 | W14: 0.054462226 | X14: 0.054506331 | Y14: 0.048944004 | Z14: 0.049376897 | AA14: 0.038221228 | AB14: 0.035346492 | AC14: 0.043017337 | AD14: 0.040418042 | AE14: 0.039325077 | AF14: 0.046593977 | AG14: 0.043630643 | AH14: 0.04307573 | AI14: 0.039617249 | AJ14: 0.040727954 | AK14: 0.035655849 | AL14: 0.041280416 | AM14: 0.041191491 | AN14: 0.041556037 | AO14: 0.044207171 | AP14: 0.052312974 | AQ14: 0.048390832 | AR14: 0.042823803 | AS14: 0.043639135 | AT14: 0.046494276 | AU14: 0.045274618 | AV14: 0.050555238
A15: HUF | B15: =FORECAST(B$1,INDEX(S15:BE15, 1, COUNTA(S15:BE15)-4):INDEX(S15:BE15, 1, COUNTA(S15:BE15)),INDEX($S$1:$BE$1, 1, COUNTA($S$1:$BE$1)-4):INDEX($S$1:$BE$1, 1, COUNTA($S$1:$BE$1))) -> 0.0047961561 | S15: 0.0097257926 | T15: 0.0078355812 | U15: 0.0088797452 | V15: 0.0077258761 | W15: 0.0078675922 | X15: 0.0086150401 | Y15: 0.0086036675 | Z15: 0.0082458163 | AA15: 0.007590007 | AB15: 0.0070697526 | AC15: 0.0074013173 | AD15: 0.00709352 | AE15: 0.0088335612 | AF15: 0.0082175514 | AG15: 0.0072351937 | AH15: 0.0069836287 | AI15: 0.0055338521 | AJ15: 0.0050498846 | AK15: 0.0051854004 | AL15: 0.0048329056 | AM15: 0.0052644274 | AN15: 0.0049304271 | AO15: 0.0054185009 | AP15: 0.005215081 | AQ15: 0.0051795734 | AR15: 0.0046819262 | AS15: 0.0040522874 | AT15: 0.0044105638 | AU15: 0.0046484661 | AV15: 0.0048347619
A16: AED | B16: =FORECAST(B$1,INDEX(S16:BE16, 1, COUNTA(S16:BE16)-4):INDEX(S16:BE16, 1, COUNTA(S16:BE16)),INDEX($S$1:$BE$1, 1, COUNTA($S$1:$BE$1)-4):INDEX($S$1:$BE$1, 1, COUNTA($S$1:$BE$1))) -> 0.47093643 | S16: #N/A | T16: #N/A | U16: #N/A | V16: 0.51055051 | W16: 0.58074252 | X16: 0.67224123 | Y16: 0.57842072 | Z16: 0.55821625 | AA16: 0.42091843 | AB16: 0.39832562 | AC16: 0.44675144 | AD16: 0.3479568 | AE16: 0.35756161 | AF16: 0.43318934 | AG16: 0.38443431 | AH16: 0.35514518 | AI16: 0.33257046 | AJ16: 0.32505824 | AK16: 0.31400987 | AL16: 0.36502541 | AM16: 0.39484707 | AN16: 0.3886491 | AO16: 0.37593743 | AP16: 0.43610132 | AQ16: 0.40878046 | AR16: 0.39239174 | AS16: 0.42922554 | AT16: 0.43752006 | AU16: 0.45125997 | AV16: 0.44710211
A17: HKD | B17: =FORECAST(B$1,INDEX(S17:BE17, 1, COUNTA(S17:BE17)-4):INDEX(S17:BE17, 1, COUNTA(S17:BE17)),INDEX($S$1:$BE$1, 1, COUNTA($S$1:$BE$1)-4):INDEX($S$1:$BE$1, 1, COUNTA($S$1:$BE$1))) -> 0.22022436 | S17: 0.18862468 | T17: 0.19032327 | U17: 0.25139368 | V17: 0.24168102 | W17: 0.27353382 | X17: 0.31658485 | Y17: 0.27238667 | Z17: 0.26284502 | AA17: 0.19821907 | AB17: 0.18823174 | AC17: 0.21122526 | AD17: 0.16349834 | AE17: 0.16842496 | AF17: 0.20519466 | AG17: 0.18177994 | AH17: 0.16768493 | AI17: 0.15730584 | AJ17: 0.15379249 | AK17: 0.14869477 | AL17: 0.17295404 | AM17: 0.18702384 | AN17: 0.18369454 | AO17: 0.17590652 | AP17: 0.20420923 | AQ17: 0.19370738 | AR17: 0.1851058 | AS17: 0.20080629 | AT17: 0.20473972 | AU17: 0.21213179 | AV17: 0.20916684
A18: MXN | B18: =FORECAST(B$1,INDEX(S18:BE18, 1, COUNTA(S18:BE18)-4):INDEX(S18:BE18, 1, COUNTA(S18:BE18)),INDEX($S$1:$BE$1, 1, COUNTA($S$1:$BE$1)-4):INDEX($S$1:$BE$1, 1, COUNTA($S$1:$BE$1))) -> 0.10019324 | S18: #N/A | T18: #N/A | U18: #N/A | V18: #N/A | W18: #N/A | X18: #N/A | Y18: 0.20923453 | Z18: 0.20583982 | AA18: 0.13482101 | AB18: 0.1363577 | AC18: 0.14458888 | AD18: 0.11865952 | AE18: 0.12663971 | AF18: 0.1208466 | AG18: 0.11479367 | AH18: 0.11023695 | AI18: 0.095390382 | AJ18: 0.096744944 | AK18: 0.088534881 | AL18: 0.088708322 | AM18: 0.083579855 | AN18: 0.076257267 | AO18: 0.07574632 | AP18: 0.080973542 | AQ18: 0.066956538 | AR18: 0.07031468 | AS18: 0.077803995 | AT18: 0.085845763 | AU18: 0.098375976 | AV18: 0.087177968
A19: ZAR | B19: =FORECAST(B$1,INDEX(S19:BE19, 1, COUNTA(S19:BE19)-4):INDEX(S19:BE19, 1, COUNTA(S19:BE19)),INDEX($S$1:$BE$1, 1, COUNTA($S$1:$BE$1)-4):INDEX($S$1:$BE$1, 1, COUNTA($S$1:$BE$1))) -> 0.088452156 | S19: 0.3374036 | T19: 0.32541212 | U19: 0.30780462 | V19: 0.31285517 | W19: 0.3147153 | X19: 0.30789205 | Y19: 0.20402223 | Z19: 0.20291755 | AA19: 0.25309161 | AB19: 0.21390871 | AC19: 0.22901951 | AD19: 0.18341639 | AE19: 0.16761026 | AF19: 0.20315058 | AG19: 0.19437318 | AH19: 0.19454019 | AI19: 0.15929224 | AJ19: 0.12984973 | AK19: 0.10917217 | AL19: 0.11206744 | AM19: 0.098220734 | AN19: 0.10634037 | AO19: 0.11646985 | AP19: 0.10427852 | AQ19: 0.086688361 | AR19: 0.096887583 | AS19: 0.095759089 | AT19: 0.088355312 | AU19: 0.089952549 | AV19: 0.092669701
A20: PHP | B20: =FORECAST(B$1,INDEX(S20:BE20, 1, COUNTA(S20:BE20)-4):INDEX(S20:BE20, 1, COUNTA(S20:BE20)),INDEX($S$1:$BE$1, 1, COUNTA($S$1:$BE$1)-4):INDEX($S$1:$BE$1, 1, COUNTA($S$1:$BE$1))) -> 0.029284208 | S20: 0.055837618 | T20: 0.055951616 | U20: 0.047172817 | V20: 0.049313378 | W20: 0.049701542 | X20: 0.04680838 | Y20: 0.040549552 | Z20: 0.040412584 | AA20: 0.027620069 | AB20: 0.026139896 | AC20: 0.030920947 | AD20: 0.027638185 | AE20: 0.02915014 | AF20: 0.03306105 | AG20: 0.031389699 | AH20: 0.030117233 | AI20: 0.028462207 | AJ20: 0.029238151 | AK20: 0.025774779 | AL20: 0.030082104 | AM20: 0.031462522 | AN20: 0.028435256 | AO20: 0.02644888 | AP20: 0.030805751 | AQ20: 0.030614498 | AR20: 0.028425603 | AS20: 0.028460107 | AT20: 0.029219716 | AU20: 0.028710901 | AV20: 0.029126333
A21: SEK | B21: =FORECAST(B$1,INDEX(S21:BE21, 1, COUNTA(S21:BE21)-4):INDEX(S21:BE21, 1, COUNTA(S21:BE21)),INDEX($S$1:$BE$1, 1, COUNTA($S$1:$BE$1)-4):INDEX($S$1:$BE$1, 1, COUNTA($S$1:$BE$1))) -> 0.16418811 | S21: 0.21818766 | T21: 0.18957397 | U21: 0.24077515 | V21: 0.22067895 | W21: 0.24237765 | X21: 0.22551561 | Y21: 0.23038418 | Z21: 0.22231361 | AA21: 0.20718154 | AB21: 0.18440257 | AC21: 0.22798521 | AD21: 0.18806365 | AE21: 0.22001165 | AF21: 0.20501018 | AG21: 0.19708937 | AH21: 0.20718925 | AI21: 0.18469601 | AJ21: 0.18342829 | AK21: 0.17874747 | AL21: 0.15503029 | AM21: 0.17859289 | AN21: 0.15912703 | AO21: 0.16515448 | AP21: 0.16213591 | AQ21: 0.17342931 | AR21: 0.16463448 | AS21: 0.15600538 | AT21: 0.1533533 | AU21: 0.15305418 | AV21: 0.17305586
A22: IDR | B22: =FORECAST(B$1,INDEX(S22:BE22, 1, COUNTA(S22:BE22)-4):INDEX(S22:BE22, 1, COUNTA(S22:BE22)),INDEX($S$1:$BE$1, 1, COUNTA($S$1:$BE$1)-4):INDEX($S$1:$BE$1, 1, COUNTA($S$1:$BE$1))) -> 0.00010252091 | S22: 0.00062767781 | T22: 0.00060586598 | U22: 0.00013538625 | V22: 0.0002769416 | W22: 0.00024409802 | X22: 0.00021812209 | Y22: 0.0002362157 | Z22: 0.00023270947 | AA22: 0.00016903929 | AB22: 0.00014951432 | AC22: 0.0001764145 | AD22: 0.00014174957 | AE22: 0.0001425434 | AF22: 0.00015570724 | AG22: 0.0001557563 | AH22: 0.0001501874 | AI22: 0.0001336833 | AJ22: 0.0001227574 | AK22: 0.0001023308 | AL22: 0.0001031814 | AM22: 0.0001101334 | AN22: 0.000107057 | AO22: 0.0001002798 | AP22: 0.0001127121 | AQ22: 0.0001031238 | AR22: 0.0001008107 | AS22: 0.00010618761 | AT22: 0.00010451423 | AU22: 0.00010291874 | AV22: 0.00010137717
A23: SAR | B23: =FORECAST(B$1,INDEX(S23:BE23, 1, COUNTA(S23:BE23)-4):INDEX(S23:BE23, 1, COUNTA(S23:BE23)),INDEX($S$1:$BE$1, 1, COUNTA($S$1:$BE$1)-4):INDEX($S$1:$BE$1, 1, COUNTA($S$1:$BE$1))) -> 0.46120375 | S23: 0.38935304 | T23: 0.39306358 | U23: 0.51937882 | V23: 0.49990525 | W23: 0.56850984 | X23: 0.65836765 | Y23: 0.56646801 | Z23: 0.54669187 | AA23: 0.41225358 | AB23: 0.39013626 | AC23: 0.43750667 | AD23: 0.34075847 | AE23: 0.35026118 | AF23: 0.42403716 | AG23: 0.376495 | AH23: 0.347813 | AI23: 0.32575074 | AJ23: 0.31835827 | AK23: 0.30749805 | AL23: 0.35744185 | AM23: 0.38670633 | AN23: 0.38064315 | AO23: 0.36816805 | AP23: 0.42708856 | AQ23: 0.40033233 | AR23: 0.38428231 | AS23: 0.42035488 | AT23: 0.42847798 | AU23: 0.44193393 | AV23: 0.437862
A24: BRL | B24: =FORECAST(B$1,INDEX(S24:BE24, 1, COUNTA(S24:BE24)-4):INDEX(S24:BE24, 1, COUNTA(S24:BE24)),INDEX($S$1:$BE$1, 1, COUNTA($S$1:$BE$1)-4):INDEX($S$1:$BE$1, 1, COUNTA($S$1:$BE$1))) -> 0.32649699 | S24: #N/A | T24: #N/A | U24: 1.6843642 | V24: #N/A | W24: 1.1838957 | X24: 1.0633687 | Y24: 0.57442602 | Z24: 0.70569947 | AA24: 0.508315 | AB24: 0.62132724 | AC24: 0.75806861 | AD24: 0.66691873 | AE24: 0.82062403 | AF24: 0.81342 | AG24: 0.79882012 | AH24: 0.80667488 | AI24: 0.66852618 | AJ24: 0.59195397 | AK24: 0.50970564 | AL24: 0.42506382 | AM24: 0.40912187 | AN24: 0.4571936 | AO24: 0.41775432 | AP24: 0.38454181 | AQ24: 0.28362956 | AR24: 0.26843373 | AS24: 0.30602428 | AT24: 0.30559553 | AU24: 0.32276642 | AV24: 0.30246325
A25: TRY | B25: =FORECAST(B$1,INDEX(S25:BE25, 1, COUNTA(S25:BE25)-4):INDEX(S25:BE25, 1, COUNTA(S25:BE25)),INDEX($S$1:$BE$1, 1, COUNTA($S$1:$BE$1)-4):INDEX($S$1:$BE$1, 1, COUNTA($S$1:$BE$1))) -> 0.0017914315 | S25: #N/A | T25: #N/A | U25: #N/A | V25: #N/A | W25: #N/A | X25: #N/A | Y25: #N/A | Z25: #N/A | AA25: #N/A | AB25: #N/A | AC25: 1.034784 | AD25: 0.98625267 | AE25: 1.0591441 | AF25: 1.036546 | AG25: 0.93061287 | AH25: 0.85128247 | AI25: 0.68490574 | AJ25: 0.66062001 | AK25: 0.53896433 | AL25: 0.51653982 | AM25: 0.51254866 | AN25: 0.39248704 | AO25: 0.34871119 | AP25: 0.27959933 | AQ25: 0.21292894 | AR25: 0.1625766 | AS25: 0.087868213 | AT25: 0.084680802 | AU25: 0.051357138 | AV25: 0.041242706
A26: KES | B26: =FORECAST(B$1,INDEX(S26:BE26, 1, COUNTA(S26:BE26)-4):INDEX(S26:BE26, 1, COUNTA(S26:BE26)),INDEX($S$1:$BE$1, 1, COUNTA($S$1:$BE$1)-4):INDEX($S$1:$BE$1, 1, COUNTA($S$1:$BE$1))) -> 0.012434772 | S26: #N/A | T26: #N/A | U26: #N/A | V26: 0.02586349 | W26: 0.027476755 | X26: 0.031183911 | Y26: 0.026875029 | Z26: 0.02601357 | AA26: 0.019454302 | AB26: 0.019174968 | AC26: 0.022382827 | AD26: 0.019174639 | AE26: 0.020097315 | AF26: 0.020951753 | AG26: 0.018265604 | AH26: 0.01565879 | AI26: 0.0147358 | AJ26: 0.013964202 | AK26: 0.013334166 | AL26: 0.014501497 | AM26: 0.014290225 | AN26: 0.013843952 | AO26: 0.013655682 | AP26: 0.015417089 | AQ26: 0.013927395 | AR26: 0.013041031 | AS26: 0.013247082 | AT26: 0.012421424 | AU26: 0.012651537 | AV26: 0.012707299
A27: KRW | B27: =FORECAST(B$1,INDEX(S27:BE27, 1, COUNTA(S27:BE27)-4):INDEX(S27:BE27, 1, COUNTA(S27:BE27)),INDEX($S$1:$BE$1, 1, COUNTA($S$1:$BE$1)-4):INDEX($S$1:$BE$1, 1, COUNTA($S$1:$BE$1))) -> 0.0012141216 | S27: 0.0017973436 | T27: 0.0016645258 | U27: 0.0014255376 | V27: 0.0016065935 | W27: 0.0019124551 | X27: 0.00189934 | Y27: 0.0017338396 | Z27: 0.0017144256 | AA27: 0.0013384122 | AB27: 0.0014213338 | AC27: 0.0017300777 | AD27: 0.0013867217 | AE27: 0.0012665749 | AF27: 0.0012451565 | AG27: 0.001253434 | AH27: 0.0012000625 | AI27: 0.0010780073 | AJ27: 0.0010745408 | AK27: 0.0010913743 | AL27: 0.0012206268 | AM27: 0.001261786 | AN27: 0.0012771201 | AO27: 0.0013019565 | AP27: 0.001331427 | AQ27: 0.0012676971 | AR27: 0.0012201922 | AS27: 0.0012076733 | AT27: 0.0012302705 | AU27: 0.0012129083 | AV27: 0.0012130719
A28: EGP | B28: =FORECAST(B$1,INDEX(S28:BE28, 1, COUNTA(S28:BE28)-4):INDEX(S28:BE28, 1, COUNTA(S28:BE28)),INDEX($S$1:$BE$1, 1, COUNTA($S$1:$BE$1)-4):INDEX($S$1:$BE$1, 1, COUNTA($S$1:$BE$1))) -> 0.0096032358 | S28: 0.42994859 | T28: 0.43523871 | U28: 0.57167507 | V28: 0.55024492 | W28: 0.61763402 | X28: 0.63731307 | Y28: 0.45985905 | Z28: 0.44255357 | AA28: 0.2460743 | AB28: 0.25233702 | AC28: 0.28656391 | AD28: 0.22468708 | AE28: 0.246397 | AF28: 0.28447908 | AG28: 0.25657483 | AH28: 0.21896547 | AI28: 0.20231829 | AJ28: 0.17544252 | AK28: 0.16548377 | AL28: 0.17576613 | AM28: 0.16330614 | AN28: 0.078539195 | AO28: 0.078313653 | AP28: 0.098252556 | AQ28: 0.093863071 | AR28: 0.091657684 | AS28: 0.083079536 | AT28: 0.051996278 | AU28: 0.035372461 | AV28: 0.033110971
A29: IQD | B29: =FORECAST(B$1,INDEX(S29:BE29, 1, COUNTA(S29:BE29)-4):INDEX(S29:BE29, 1, COUNTA(S29:BE29)),INDEX($S$1:$BE$1, 1, COUNTA($S$1:$BE$1)-4):INDEX($S$1:$BE$1, 1, COUNTA($S$1:$BE$1))) -> 0.0013531243 | S29: #N/A | T29: #N/A | U29: #N/A | V29: #N/A | W29: #N/A | X29: 7.9419171 | Y29: 6.8330561 | Z29: 6.5941763 | AA29: 0.0010578047 | AB29: 0.00099880531 | AC29: 0.0011168482 | AD29: 0.0010236201 | AE29: 0.0010984941 | AF29: 0.0013624384 | AG29: 0.0012082762 | AH29: 0.0011068114 | AI29: 0.001048132 | AJ29: 0.0010267803 | AK29: 0.0009900471 | AL29: 0.0011519951 | AM29: 0.0013107547 | AN29: 0.0012071458 | AO29: 0.0011652609 | AP29: 0.0013394202 | AQ29: 0.0012618839 | AR29: 0.0009870817 | AS29: 0.0010799742 | AT29: 0.0011012111 | AU29: 0.0012656139 | AV29: 0.0012536315
A30: NOK | B30: =FORECAST(B$1,INDEX(S30:BE30, 1, COUNTA(S30:BE30)-4):INDEX(S30:BE30, 1, COUNTA(S30:BE30)),INDEX($S$1:$BE$1, 1, COUNTA($S$1:$BE$1)-4):INDEX($S$1:$BE$1, 1, COUNTA($S$1:$BE$1))) -> 0.15393851 | S30: 0.22440017 | T30: 0.20070649 | U30: 0.25059729 | V30: 0.23775006 | W30: 0.24836298 | X30: 0.26271605 | Y30: 0.286362 | Z30: 0.27391722 | AA30: 0.22326833 | AB30: 0.22222982 | AC30: 0.26392709 | AD30: 0.21979698 | AE30: 0.25950486 | AF30: 0.24813295 | AG30: 0.2389867 | AH30: 0.23718504 | AI30: 0.21465811 | AJ30: 0.2049976 | AK30: 0.19275602 | AL30: 0.167417 | AM30: 0.17444274 | AN30: 0.1658807 | AO30: 0.17606777 | AP30: 0.17560159 | AQ30: 0.16782648 | AR30: 0.16701888 | AS30: 0.16387087 | AT30: 0.15229282 | AU30: 0.15314631 | AV30: 0.16262679
A31: KWD | B31: =FORECAST(B$1,INDEX(S31:BE31, 1, COUNTA(S31:BE31)-4):INDEX(S31:BE31, 1, COUNTA(S31:BE31)),INDEX($S$1:$BE$1, 1, COUNTA($S$1:$BE$1)-4):INDEX($S$1:$BE$1, 1, COUNTA($S$1:$BE$1))) -> 5.6130191 | S31: #N/A | T31: #N/A | U31: #N/A | V31: 6.1101341 | W31: 6.9679613 | X31: 8.0140929 | Y31: 7.0394496 | Z31: 6.7915118 | AA31: 5.2454142 | AB31: 5.0095874 | AC31: 5.6738484 | AD31: 4.4357746 | AE31: 4.9581468 | AF31: 5.529532 | AG31: 4.8931975 | AH31: 4.7040182 | AI31: 4.3981918 | AJ31: 4.1807644 | AK31: 4.0930443 | AL31: 4.4602665 | AM31: 4.805484 | AN31: 4.6805471 | AO31: 4.5938013 | AP31: 5.2574406 | AQ31: 4.9100735 | AR31: 4.7826471 | AS31: 5.1414684 | AT31: 5.2375716 | AU31: 5.389742 | AV31: 5.3722993
A32: RUB | B32: =FORECAST(B$1,INDEX(S32:BE32, 1, COUNTA(S32:BE32)-4):INDEX(S32:BE32, 1, COUNTA(S32:BE32)),INDEX($S$1:$BE$1, 1, COUNTA($S$1:$BE$1)-4):INDEX($S$1:$BE$1, 1, COUNTA($S$1:$BE$1))) -> 0.01968363 | S32: #N/A | T32: #N/A | U32: #N/A | V32: #N/A | W32: #N/A | X32: #N/A | Y32: #N/A | Z32: #N/A | AA32: #N/A | AB32: 0.051101099 | AC32: 0.061086082 | AD32: 0.049825131 | AE32: 0.056172249 | AF32: 0.05089006 | AG32: 0.048246386 | AH32: 0.04619742 | AI32: 0.04166432 | AJ32: 0.0383855 | AK32: 0.032849758 | AL32: 0.023319004 | AM32: 0.021351076 | AN32: 0.025374631 | AO32: 0.024132977 | AP32: 0.024492656 | AQ32: 0.020624964 | AR32: 0.019821757 | AS32: 0.025250649 | AT32: 0.021322485 | AU32: 0.018156005 | AV32: 0.020993623
A33: DKK | B33: =FORECAST(B$1,INDEX(S33:BE33, 1, COUNTA(S33:BE33)-4):INDEX(S33:BE33, 1, COUNTA(S33:BE33)),INDEX($S$1:$BE$1, 1, COUNTA($S$1:$BE$1)-4):INDEX($S$1:$BE$1, 1, COUNTA($S$1:$BE$1))) -> 0.26203966 | S33: 0.24850043 | T33: 0.22061657 | U33: 0.28059464 | V33: 0.25843939 | W33: 0.27279889 | X33: 0.28045301 | Y33: 0.28188923 | Z33: 0.27138511 | AA33: 0.25595696 | AB33: 0.23469257 | AC33: 0.28122938 | AD33: 0.23403106 | AE33: 0.27958206 | AF33: 0.2994656 | AG33: 0.25747931 | AH33: 0.24857955 | AI33: 0.21906175 | AJ33: 0.20570481 | AK33: 0.21329303 | AL33: 0.19323253 | AM33: 0.22154525 | AN33: 0.20464644 | AO33: 0.22828601 | AP33: 0.23456053 | AQ33: 0.23970491 | AR33: 0.22471017 | AS33: 0.21741504 | AT33: 0.23141764 | AU33: 0.24028952 | AV33: 0.25904617
A34: PKR | B34: =FORECAST(B$1,INDEX(S34:BE34, 1, COUNTA(S34:BE34)-4):INDEX(S34:BE34, 1, COUNTA(S34:BE34)),INDEX($S$1:$BE$1, 1, COUNTA($S$1:$BE$1)-4):INDEX($S$1:$BE$1, 1, COUNTA($S$1:$BE$1))) -> 0.0047151148 | S34: 0.041645244 | T34: 0.036480411 | U34: 0.042115742 | V34: 0.036476549 | W34: 0.04092507 | X34: 0.038762041 | Y34: 0.03598629 | Z34: 0.034140347 | AA34: 0.026692565 | AB34: 0.024609756 | AC34: 0.02722461 | AD34: 0.021130781 | AE34: 0.019103411 | AF34: 0.019488212 | AG34: 0.016748888 | AH34: 0.015289852 | AI34: 0.013473753 | AJ34: 0.01212735 | AK34: 0.01174308 | AL34: 0.013161514 | AM34: 0.013842505 | AN34: 0.013614209 | AO34: 0.011928886 | AP34: 0.010212618 | AQ34: 0.0089262542 | AR34: 0.008441056 | AS34: 0.0065670918 | AT34: 0.0057055713 | AU34: 0.005958152 | AV34: 0.0057850702
A35: ILS | B35: =FORECAST(B$1,INDEX(S35:BE35, 1, COUNTA(S35:BE35)-4):INDEX(S35:BE35, 1, COUNTA(S35:BE35)),INDEX($S$1:$BE$1, 1, COUNTA($S$1:$BE$1)-4):INDEX($S$1:$BE$1, 1, COUNTA($S$1:$BE$1))) -> 0.47699379 | S35: 0.45565553 | T35: 0.42057375 | U35: 0.52999735 | V35: 0.46054892 | W35: 0.52298164 | X35: 0.59141127 | Y35: 0.4385411 | Z35: 0.43065372 | AA35: 0.34598951 | AB35: 0.31805436 | AC35: 0.37060086 | AD35: 0.30416582 | AE35: 0.40182299 | AF35: 0.41060864 | AG35: 0.38260319 | AH35: 0.37614095 | AI35: 0.32928053 | AJ35: 0.32780057 | AK35: 0.33173403 | AL35: 0.33797406 | AM35: 0.38383534 | AN35: 0.39315565 | AO35: 0.39506031 | AP35: 0.45994166 | AQ35: 0.44093824 | AR35: 0.44778854 | AS35: 0.46852884 | AT35: 0.44304896 | AU35: 0.44825838 | AV35: 0.48777888
A36: PLN | B36: =FORECAST(B$1,INDEX(S36:BE36, 1, COUNTA(S36:BE36)-4):INDEX(S36:BE36, 1, COUNTA(S36:BE36)),INDEX($S$1:$BE$1, 1, COUNTA($S$1:$BE$1)-4):INDEX($S$1:$BE$1, 1, COUNTA($S$1:$BE$1))) -> 0.46727406 | S36: #N/A | T36: #N/A | U36: #N/A | V36: #N/A | W36: #N/A | X36: #N/A | Y36: 0.51400192 | Z36: 0.50216419 | AA36: 0.42119369 | AB36: 0.43550932 | AC36: 0.51460072 | AD36: 0.46427832 | AE36: 0.62184292 | AF36: 0.51069208 | AG36: 0.49916872 | AH36: 0.46074547 | AI36: 0.39251907 | AJ36: 0.36700479 | AK36: 0.38134146 | AL36: 0.35538873 | AM36: 0.38856399 | AN36: 0.35936454 | AO36: 0.40322647 | AP36: 0.3993854 | AQ36: 0.40554158 | AR36: 0.36511962 | AS36: 0.34322447 | AT36: 0.36677501 | AU36: 0.41980645 | AV36: 0.45548266
A37: QAR | B37: =FORECAST(B$1,INDEX(S37:BE37, 1, COUNTA(S37:BE37)-4):INDEX(S37:BE37, 1, COUNTA(S37:BE37)),INDEX($S$1:$BE$1, 1, COUNTA($S$1:$BE$1)-4):INDEX($S$1:$BE$1, 1, COUNTA($S$1:$BE$1))) -> 0.47514122 | S37: #N/A | T37: #N/A | U37: #N/A | V37: 0.51564759 | W37: 0.58584865 | X37: 0.67828788 | Y37: 0.58358246 | Z37: 0.56321742 | AA37: 0.42475779 | AB37: 0.40196442 | AC37: 0.45299299 | AD37: 0.35110595 | AE37: 0.3607391 | AF37: 0.4367586 | AG37: 0.38780257 | AH37: 0.35819778 | AI37: 0.3354794 | AJ37: 0.32793328 | AK37: 0.31672168 | AL37: 0.3682821 | AM37: 0.3982603 | AN37: 0.39203808 | AO37: 0.37929401 | AP37: 0.43999508 | AQ37: 0.41243028 | AR37: 0.39589524 | AS37: 0.43305791 | AT37: 0.44142649 | AU37: 0.45528907 | AV37: 0.45109409
A38: XAU | B38: =FORECAST(B$1,INDEX(S38:BE38, 1, COUNTA(S38:BE38)-4):INDEX(S38:BE38, 1, COUNTA(S38:BE38)),INDEX($S$1:$BE$1, 1, COUNTA($S$1:$BE$1)-4):INDEX($S$1:$BE$1, 1, COUNTA($S$1:$BE$1))) -> 5584.9573 | S38: #N/A | T38: 489.69171 | U38: 572.84311 | V38: 493.56601 | W38: 615.45842 | X38: 668.14984 | Y38: 683.33201 | Z38: 643.71124 | AA38: 615.50273 | AB38: 625.16127 | AC38: 1007.6872 | AD38: 839.91313 | AE38: 1238.091 | AF38: 1477.2845 | AG38: 1590.8765 | AH38: 1861.6634 | AI38: 2038.4864 | AJ38: 1909.3915 | AK38: 1477.2962 | AL38: 1611.422 | AM38: 1760.2708 | AN38: 1783.0277 | AO38: 1829.6938 | AP38: 2377.9566 | AQ38: 3070.0426 | AR38: 2539.0845 | AS38: 2787.4036 | AT38: 3059.9015 | AU38: 3892.059 | AV38: 5401.652
A39: OMR | B39: =FORECAST(B$1,INDEX(S39:BE39, 1, COUNTA(S39:BE39)-4):INDEX(S39:BE39, 1, COUNTA(S39:BE39)),INDEX($S$1:$BE$1, 1, COUNTA($S$1:$BE$1)-4):INDEX($S$1:$BE$1, 1, COUNTA($S$1:$BE$1))) -> 4.4924475 | S39: #N/A | T39: #N/A | U39: #N/A | V39: 4.9339332 | W39: 5.5410503 | X39: 6.4150222 | Y39: 5.5318035 | Z39: 5.325149 | AA39: 4.0149411 | AB39: 3.8006235 | AC39: 4.2611519 | AD39: 3.3193688 | AE39: 3.4113235 | AF39: 4.1303812 | AG39: 3.6668776 | AH39: 3.3875529 | AI39: 3.1729815 | AJ39: 3.1015429 | AK39: 2.9966366 | AL39: 3.4827435 | AM39: 3.7657106 | AN39: 3.7045518 | AO39: 3.5907157 | AP39: 4.165363 | AQ39: 3.9044115 | AR39: 3.7478769 | AS39: 4.09969 | AT39: 4.1736305 | AU39: 4.3057092 | AV39: 4.2674832
A40: COP | B40: =FORECAST(B$1,INDEX(S40:BE40, 1, COUNTA(S40:BE40)-4):INDEX(S40:BE40, 1, COUNTA(S40:BE40)),INDEX($S$1:$BE$1, 1, COUNTA($S$1:$BE$1)-4):INDEX($S$1:$BE$1, 1, COUNTA($S$1:$BE$1))) -> 0.00041601814 | S40: #N/A | T40: #N/A | U40: #N/A | V40: 0.0010735154 | W40: 0.001037565 | X40: 0.0010927793 | Y40: 0.0007551835 | Z40: 0.00086741249 | AA40: 0.00057655543 | AB40: 0.00062948165 | AC40: 0.0006257485 | AD40: 0.00064691959 | AE40: 0.00072261873 | AF40: 0.00076033377 | AG40: 0.0007373009 | AH40: 0.0006973415 | AI40: 0.0006824569 | AJ40: 0.0006554844 | AK40: 0.0005867056 | AL40: 0.0005203316 | AM40: 0.0004804412 | AN40: 0.0004966771 | AO40: 0.0004948828 | AP40: 0.0004586073 | AQ40: 0.0003965943 | AR40: 0.0003810534 | AS40: 0.00037244087 | AT40: 0.00033933658 | AU40: 0.00042839807 | AV40: 0.00040452155
...

Sheet fi
A1: today: https://tradingeconomics.com/new-zealand/consumer-price-index-cpi | F1: linear, 5 month fit for inflation | K1: today | L1: index estimate for today | M1: Extrapolation of inflation into the future based on the last 5 quarters for which we have data
A2: https://www.stats.govt.nz/large-datasets/csv-files-for-download/ | K2: =YEAR(TODAY()) -> 2026 | L2: =L3*(1+M2)^(K2-K3) -> 1340.3609 | M2: =AVERAGE(OFFSET(H1,COUNT(H:H),0,5,1)) -> 0.024708811
A3: Year | B3: Quarter | C3: YQ | D3: Date | E3: CPI | F3: Inflation (2 quarter central estimate) | G3: CPIY | H3: Inflation (rolling 5 quarter linear fit) | K3: {=MAX(_xlfn._xlws.FILTER(A2:A1000, COUNTIF(A2:A1000, A2:A1000) >= 4))} -> 2024 | L3: =INDEX(G:G,MATCH(K3,A:A,0)) -> 1276.5
A4: 1950 | B4: Q1 | C4: 1950Q1 | D4: 18352 | E4: 27.956111 | F4: 0.066666712 | G4: {=AVERAGE(IF(A1:A7=A4,E1:E7))} -> 29.216877
A5: 1950 | B5: Q2 | C5: =CONCATENATE(A5,B5) -> 1950Q2 | D5: =DATE(YEAR(D4),MONTH(D4)+3,DAY(D4)) -> 18444 | E5: 28.833165 | F5: =SUMPRODUCT(E4:E6,TRANSPOSE({-1,0,1}))/2/E5*4 -> 0.12737644 | G5: {=AVERAGE(IF(A2:A8=A5,E2:E8))} -> 29.216877 | K5: Any year
A6: 1950 | B6: Q3 | C6: =CONCATENATE(A6,B6) -> 1950Q3 | D6: =DATE(YEAR(D5),MONTH(D5)+3,DAY(D5)) -> 18536 | E6: 29.792444 | F6: =SUMPRODUCT(E5:E7,TRANSPOSE({-1,0,1}))/2/E6*4 -> 0.097516068 | G6: {=AVERAGE(IF(A3:A9=A6,E3:E9))} -> 29.216877 | H6: =SUMPRODUCT(E4:E8,TRANSPOSE({-2,-1,0,1,2}))/10/E6*4 -> 0.093836236 | K6: 2004 | L6: =INDEX(G:G,MATCH(K3,A:A,0))*(1+AVERAGE(OFFSET(H1,COUNT(H:H),0,5,1)))^(K6-K3) -> 783.45023
A7: 1950 | B7: Q4 | C7: =CONCATENATE(A7,B7) -> 1950Q4 | D7: =DATE(YEAR(D6),MONTH(D6)+3,DAY(D6)) -> 18627 | E7: 30.285786 | F7: =SUMPRODUCT(E6:E8,TRANSPOSE({-1,0,1}))/2/E7*4 -> 0.061538439 | G7: {=AVERAGE(IF(A4:A10=A7,E4:E10))} -> 29.216877 | H7: =SUMPRODUCT(E5:E9,TRANSPOSE({-2,-1,0,1,2}))/10/E7*4 -> 0.097013589 | I7: =SUMPRODUCT(E6:E8,TRANSPOSE({-1,0,1}))/2/E7*4 -> 0.061538439
A8: =A4+1 -> 1951 | B8: Q1 | C8: =CONCATENATE(A8,B8) -> 1951Q1 | D8: =DATE(YEAR(D7),MONTH(D7)+3,DAY(D7)) -> 18717 | E8: 30.724314 | F8: =SUMPRODUCT(E7:E9,TRANSPOSE({-1,0,1}))/2/E8*4 -> 0.11418383 | G8: {=AVERAGE(IF(A5:A11=A8,E5:E11))} -> 32.437311 | H8: =SUMPRODUCT(E6:E10,TRANSPOSE({-2,-1,0,1,2}))/10/E8*4 -> 0.10847456 | I8: =SUMPRODUCT(E7:E9,TRANSPOSE({-1,0,1}))/2/E8*4 -> 0.11418383
A9: =A5+1 -> 1951 | B9: Q2 | C9: =CONCATENATE(A9,B9) -> 1951Q2 | D9: =DATE(YEAR(D8),MONTH(D8)+3,DAY(D8)) -> 18809 | E9: 32.039896 | F9: =SUMPRODUCT(E8:E10,TRANSPOSE({-1,0,1}))/2/E9*4 -> 0.14713425 | G9: {=AVERAGE(IF(A6:A12=A9,E6:E12))} -> 32.437311 | H9: =SUMPRODUCT(E7:E11,TRANSPOSE({-2,-1,0,1,2}))/10/E9*4 -> 0.11976048
A10: =A6+1 -> 1951 | B10: Q3 | C10: =CONCATENATE(A10,B10) -> 1951Q3 | D10: =DATE(YEAR(D9),MONTH(D9)+3,DAY(D9)) -> 18901 | E10: 33.081397 | F10: =SUMPRODUCT(E9:E11,TRANSPOSE({-1,0,1}))/2/E10*4 -> 0.11267602 | G10: {=AVERAGE(IF(A7:A13=A10,E7:E13))} -> 32.437311 | H10: =SUMPRODUCT(E8:E12,TRANSPOSE({-2,-1,0,1,2}))/10/E10*4 -> 0.11002483
A11: =A7+1 -> 1951 | B11: Q4 | C11: =CONCATENATE(A11,B11) -> 1951Q4 | D11: =DATE(YEAR(D10),MONTH(D10)+3,DAY(D10)) -> 18992 | E11: 33.903636 | F11: =SUMPRODUCT(E10:E12,TRANSPOSE({-1,0,1}))/2/E11*4 -> 0.074373498 | G11: {=AVERAGE(IF(A8:A14=A11,E8:E14))} -> 32.437311 | H11: =SUMPRODUCT(E9:E13,TRANSPOSE({-2,-1,0,1,2}))/10/E11*4 -> 0.080194018
A12: =A8+1 -> 1952 | B12: Q1 | C12: =CONCATENATE(A12,B12) -> 1952Q1 | D12: =DATE(YEAR(D11),MONTH(D11)+3,DAY(D11)) -> 19083 | E12: 34.342163 | F12: =SUMPRODUCT(E11:E13,TRANSPOSE({-1,0,1}))/2/E12*4 -> 0.052673619 | G12: {=AVERAGE(IF(A9:A15=A12,E9:E15))} -> 34.95199 | H12: =SUMPRODUCT(E10:E14,TRANSPOSE({-2,-1,0,1,2}))/10/E12*4 -> 0.059696752
A13: =A9+1 -> 1952 | B13: Q2 | C13: =CONCATENATE(A13,B13) -> 1952Q2 | D13: =DATE(YEAR(D12),MONTH(D12)+3,DAY(D12)) -> 19175 | E13: 34.808099 | F13: =SUMPRODUCT(E12:E14,TRANSPOSE({-1,0,1}))/2/E13*4 -> 0.048818926 | G13: {=AVERAGE(IF(A10:A16=A13,E10:E16))} -> 34.95199 | H13: =SUMPRODUCT(E11:E15,TRANSPOSE({-2,-1,0,1,2}))/10/E13*4 -> 0.045669291
A14: =A10+1 -> 1952 | B14: Q3 | C14: =CONCATENATE(A14,B14) -> 1952Q3 | D14: =DATE(YEAR(D13),MONTH(D13)+3,DAY(D13)) -> 19267 | E14: 35.19181 | F14: =SUMPRODUCT(E13:E15,TRANSPOSE({-1,0,1}))/2/E14*4 -> 0.03738313 | G14: {=AVERAGE(IF(A11:A17=A14,E11:E17))} -> 34.95199 | H14: =SUMPRODUCT(E12:E16,TRANSPOSE({-2,-1,0,1,2}))/10/E14*4 -> 0.041121477
A15: =A11+1 -> 1952 | B15: Q4 | C15: =CONCATENATE(A15,B15) -> 1952Q4 | D15: =DATE(YEAR(D14),MONTH(D14)+3,DAY(D14)) -> 19358 | E15: 35.465889 | F15: =SUMPRODUCT(E14:E16,TRANSPOSE({-1,0,1}))/2/E15*4 -> 0.035548637 | G15: {=AVERAGE(IF(A12:A18=A15,E12:E18))} -> 34.95199 | H15: =SUMPRODUCT(E13:E17,TRANSPOSE({-2,-1,0,1,2}))/10/E15*4 -> 0.039258094
A16: =A12+1 -> 1953 | B16: Q1 | C16: =CONCATENATE(A16,B16) -> 1953Q1 | D16: =DATE(YEAR(D15),MONTH(D15)+3,DAY(D15)) -> 19448 | E16: 35.822192 | F16: =SUMPRODUCT(E15:E17,TRANSPOSE({-1,0,1}))/2/E16*4 -> 0.042846233 | G16: {=AVERAGE(IF(A13:A19=A16,E13:E19))} -> 36.534799 | H16: =SUMPRODUCT(E14:E18,TRANSPOSE({-2,-1,0,1,2}))/10/E16*4 -> 0.041009942
A17: =A13+1 -> 1953 | B17: Q2 | C17: =CONCATENATE(A17,B17) -> 1953Q2 | D17: =DATE(YEAR(D16),MONTH(D16)+3,DAY(D16)) -> 19540 | E17: 36.233312 | F17: =SUMPRODUCT(E16:E18,TRANSPOSE({-1,0,1}))/2/E17*4 -> 0.045385804 | G17: {=AVERAGE(IF(A14:A20=A17,E14:E20))} -> 36.534799 | H17: =SUMPRODUCT(E15:E19,TRANSPOSE({-2,-1,0,1,2}))/10/E17*4 -> 0.052647519
A18: =A14+1 -> 1953 | B18: Q3 | C18: =CONCATENATE(A18,B18) -> 1953Q3 | D18: =DATE(YEAR(D17),MONTH(D17)+3,DAY(D17)) -> 19632 | E18: 36.644431 | F18: =SUMPRODUCT(E17:E19,TRANSPOSE({-1,0,1}))/2/E18*4 -> 0.065819005 | G18: {=AVERAGE(IF(A15:A21=A18,E15:E21))} -> 36.534799 | H18: =SUMPRODUCT(E16:E20,TRANSPOSE({-2,-1,0,1,2}))/10/E18*4 -> 0.055048648
A19: =A15+1 -> 1953 | B19: Q4 | C19: =CONCATENATE(A19,B19) -> 1953Q4 | D19: =DATE(YEAR(D18),MONTH(D18)+3,DAY(D18)) -> 19723 | E19: 37.439262 | F19: =SUMPRODUCT(E18:E20,TRANSPOSE({-1,0,1}))/2/E19*4 -> 0.058565204 | G19: {=AVERAGE(IF(A16:A22=A19,E16:E22))} -> 36.534799 | H19: =SUMPRODUCT(E17:E21,TRANSPOSE({-2,-1,0,1,2}))/10/E19*4 -> 0.057393856
A20: =A16+1 -> 1954 | B20: Q1 | C20: =CONCATENATE(A20,B20) -> 1954Q1 | D20: =DATE(YEAR(D19),MONTH(D19)+3,DAY(D19)) -> 19813 | E20: 37.74075 | F20: =SUMPRODUCT(E19:E21,TRANSPOSE({-1,0,1}))/2/E20*4 -> 0.049382696 | G20: {=AVERAGE(IF(A17:A23=A20,E17:E23))} -> 38.220389 | H20: =SUMPRODUCT(E18:E22,TRANSPOSE({-2,-1,0,1,2}))/10/E20*4 -> 0.047639795
... A291: =A287+1 -> 2021 | B291: Q4 | C291: =CONCATENATE(A291,B291) -> 2021Q4 | D291: =DATE(YEAR(D290),MONTH(D290)+3,DAY(D290)) -> 44560 | E291: 1122 | F291: =SUMPRODUCT(E290:E292,TRANSPOSE({-1,0,1}))/2/E291*4 -> 0.064171123 | G291: {=AVERAGE(IF(A288:A294=A291,E288:E294))} -> 1094.5 | H291: =SUMPRODUCT(E289:E293,TRANSPOSE({-2,-1,0,1,2}))/10/E291*4 -> 0.06916221
A292: =A288+1 -> 2022 | B292: Q1 | C292: =CONCATENATE(A292,B292) -> 2022Q1 | D292: =DATE(YEAR(D291),MONTH(D291)+3,DAY(D291)) -> 44650 | E292: 1142 | F292: =SUMPRODUCT(E291:E293,TRANSPOSE({-1,0,1}))/2/E292*4 -> 0.068301226 | G292: {=AVERAGE(IF(A289:A295=A292,E289:E295))} -> 1173 | H292: =SUMPRODUCT(E290:E294,TRANSPOSE({-2,-1,0,1,2}))/10/E292*4 -> 0.069702277 | J292: =AVERAGE(H288:H292) -> 0.063010253
A293: =A289+1 -> 2022 | B293: Q2 | C293: =CONCATENATE(A293,B293) -> 2022Q2 | D293: =DATE(YEAR(D292),MONTH(D292)+3,DAY(D292)) -> 44742 | E293: 1161 | F293: =SUMPRODUCT(E292:E294,TRANSPOSE({-1,0,1}))/2/E293*4 -> 0.075796727 | G293: {=AVERAGE(IF(A290:A296=A293,E290:E296))} -> 1173 | H293: =SUMPRODUCT(E291:E295,TRANSPOSE({-2,-1,0,1,2}))/10/E293*4 -> 0.070973299 | J293: =AVERAGE(H289:H293) -> 0.067691804
A294: =A290+1 -> 2022 | B294: Q3 | C294: =CONCATENATE(A294,B294) -> 2022Q3 | D294: =DATE(YEAR(D293),MONTH(D293)+3,DAY(D293)) -> 44834 | E294: 1186 | F294: =SUMPRODUCT(E293:E295,TRANSPOSE({-1,0,1}))/2/E294*4 -> 0.070826307 | G294: {=AVERAGE(IF(A291:A297=A294,E291:E297))} -> 1173 | H294: =SUMPRODUCT(E292:E296,TRANSPOSE({-2,-1,0,1,2}))/10/E294*4 -> 0.065430017 | J294: =AVERAGE(H290:H294) -> 0.068652114
A295: =A291+1 -> 2022 | B295: Q4 | C295: =CONCATENATE(A295,B295) -> 2022Q4 | D295: =DATE(YEAR(D294),MONTH(D294)+3,DAY(D294)) -> 44925 | E295: 1203 | F295: =SUMPRODUCT(E294:E296,TRANSPOSE({-1,0,1}))/2/E295*4 -> 0.053200333 | G295: {=AVERAGE(IF(A292:A298=A295,E292:E298))} -> 1173 | H295: =SUMPRODUCT(E293:E297,TRANSPOSE({-2,-1,0,1,2}))/10/E295*4 -> 0.057190357 | J295: =AVERAGE(H291:H295) -> 0.066491632
A296: =A292+1 -> 2023 | B296: Q1 | C296: =CONCATENATE(A296,B296) -> 2023Q1 | D296: =DATE(YEAR(D295),MONTH(D295)+3,DAY(D295)) -> 45015 | E296: 1218 | F296: =SUMPRODUCT(E295:E297,TRANSPOSE({-1,0,1}))/2/E296*4 -> 0.045977011 | G296: {=AVERAGE(IF(A293:A299=A296,E293:E299))} -> 1240.25 | H296: =SUMPRODUCT(E294:E298,TRANSPOSE({-2,-1,0,1,2}))/10/E296*4 -> 0.05320197 | J296: =AVERAGE(H292:H296) -> 0.063299584
A297: =A293+1 -> 2023 | B297: Q2 | C297: =CONCATENATE(A297,B297) -> 2023Q2 | D297: =DATE(YEAR(D296),MONTH(D296)+3,DAY(D296)) -> 45107 | E297: 1231 | F297: =SUMPRODUCT(E296:E298,TRANSPOSE({-1,0,1}))/2/E297*4 -> 0.056864338 | G297: {=AVERAGE(IF(A294:A300=A297,E294:E300))} -> 1240.25 | H297: =SUMPRODUCT(E295:E299,TRANSPOSE({-2,-1,0,1,2}))/10/E297*4 -> 0.047766044 | J297: =AVERAGE(H293:H297) -> 0.058912337
A298: =A294+1 -> 2023 | B298: Q3 | C298: =CONCATENATE(A298,B298) -> 2023Q3 | D298: =DATE(YEAR(D297),MONTH(D297)+3,DAY(D297)) -> 45199 | E298: 1253 | F298: =SUMPRODUCT(E297:E299,TRANSPOSE({-1,0,1}))/2/E298*4 -> 0.044692737 | G298: {=AVERAGE(IF(A295:A301=A298,E295:E301))} -> 1240.25 | H298: =SUMPRODUCT(E294:E298,TRANSPOSE({-2,-1,0,1,2}))/10/E298*4 -> 0.051715882 | J298: =AVERAGE(H294:H298) -> 0.055060854
A299: =A295+1 -> 2023 | B299: Q4 | C299: =CONCATENATE(A299,B299) -> 2023Q4 | D299: =DATE(YEAR(D298),MONTH(D298)+3,DAY(D298)) -> 45290 | E299: 1259 | F299: =SUMPRODUCT(E297:E299,TRANSPOSE({-1,0,1}))/2/E299*4 -> 0.044479746 | G299: {=AVERAGE(IF(A296:A302=A299,E296:E302))} -> 1240.25 | H299: =SUMPRODUCT(E295:E299,TRANSPOSE({-2,-1,0,1,2}))/10/E299*4 -> 0.046703733 | J299: =AVERAGE(H295:H299) -> 0.051315597
A300: =A296+1 -> 2024 | B300: Q1 | C300: =CONCATENATE(A300,B300) -> 2024Q1 | D300: =DATE(YEAR(D299),MONTH(D299)+3,DAY(D299)) -> 45381 | E300: 1267 | F300: =SUMPRODUCT(E298:E300,TRANSPOSE({-1,0,1}))/2/E300*4 -> 0.022099448 | G300: {=AVERAGE(IF(A297:A303=A300,E297:E303))} -> 1276.5 | H300: =SUMPRODUCT(E296:E300,TRANSPOSE({-2,-1,0,1,2}))/10/E300*4 -> 0.039779006 | J300: =AVERAGE(H296:H300) -> 0.047833327
A301: =A297+1 -> 2024 | B301: Q2 | C301: =CONCATENATE(A301,B301) -> 2024Q2 | D301: =DATE(YEAR(D300),MONTH(D300)+3,DAY(D300)) -> 45473 | E301: 1272 | F301: =SUMPRODUCT(E299:E301,TRANSPOSE({-1,0,1}))/2/E301*4 -> 0.020440252 | G301: {=AVERAGE(IF(A298:A304=A301,E298:E304))} -> 1276.5 | H301: =SUMPRODUCT(E297:E301,TRANSPOSE({-2,-1,0,1,2}))/10/E301*4 -> 0.030188679 | J301: =AVERAGE(H297:H301) -> 0.043230669
A302: =A298+1 -> 2024 | B302: Q3 | C302: =CONCATENATE(A302,B302) -> 2024Q3 | D302: =DATE(YEAR(D301),MONTH(D301)+3,DAY(D301)) -> 45565 | E302: 1280 | F302: =SUMPRODUCT(E300:E302,TRANSPOSE({-1,0,1}))/2/E302*4 -> 0.0203125 | G302: {=AVERAGE(IF(A299:A305=A302,E299:E305))} -> 1276.5 | H302: =SUMPRODUCT(E298:E302,TRANSPOSE({-2,-1,0,1,2}))/10/E302*4 -> 0.0209375 | J302: =AVERAGE(H298:H302) -> 0.03786496
A303: =A299+1 -> 2024 | B303: Q4 | C303: =CONCATENATE(A303,B303) -> 2024Q4 | D303: =DATE(YEAR(D302),MONTH(D302)+3,DAY(D302)) -> 45656 | E303: 1287 | F303: =SUMPRODUCT(E301:E303,TRANSPOSE({-1,0,1}))/2/E303*4 -> 0.023310023 | G303: {=AVERAGE(IF(A300:A306=A303,E300:E306))} -> 1276.5 | H303: =SUMPRODUCT(E299:E303,TRANSPOSE({-2,-1,0,1,2}))/10/E303*4 -> 0.021445221 | J303: =AVERAGE(H299:H303) -> 0.031810828
A304: =A300+1 -> 2025 | B304: Q1 | C304: =CONCATENATE(A304,B304) -> 2025Q1 | D304: =DATE(YEAR(D303),MONTH(D303)+3,DAY(D303)) -> 45746 | E304: 1299 | F304: =SUMPRODUCT(E302:E304,TRANSPOSE({-1,0,1}))/2/E304*4 -> 0.029253272 | G304: {=AVERAGE(IF(A301:A307=A304,E301:E307))} -> 1302.5 | H304: =SUMPRODUCT(E300:E304,TRANSPOSE({-2,-1,0,1,2}))/10/E304*4 -> 0.024326405 | J304: =AVERAGE(H300:H304) -> 0.027335362
A305: =A301+1 -> 2025 | B305: Q2 | C305: =CONCATENATE(A305,B305) -> 2025Q2 | D305: =DATE(YEAR(D304),MONTH(D304)+3,DAY(D304)) -> 45838 | E305: 1306 | F305: =SUMPRODUCT(E303:E305,TRANSPOSE({-1,0,1}))/2/E305*4 -> 0.029096478 | G305: {=AVERAGE(IF(A302:A308=A305,E302:E308))} -> 1302.5 | H305: =SUMPRODUCT(E301:E305,TRANSPOSE({-2,-1,0,1,2}))/10/E305*4 -> 0.026646248 | J305: =AVERAGE(H301:H305) -> 0.024708811

Sheet EXCH CALC
A1: USD | B1: US Dollar | C1: 0.60901989 | D1: 1.6419825 | E1: USD | F1: US Dollar | G1: =1/INDEX(C:C,MATCH(E1,A:A,0)) -> 1.6419825
A2: EUR | B2: Euro | C2: 0.51740598 | D2: 1.9327183 | E2: EUR | F2: Euro | G2: =1/INDEX(C:C,MATCH(E2,A:A,0)) -> 1.9327183
A3: GBP | B3: British Pound | C3: 0.44385107 | D3: 2.2530079 | E3: GBP | F3: British Pound | G3: =1/INDEX(C:C,MATCH(E3,A:A,0)) -> 2.2530079
A4: INR | B4: Indian Rupee | C4: 52.210498 | D4: 0.019153236 | E4: INR | F4: Indian Rupee | G4: =1/INDEX(C:C,MATCH(E4,A:A,0)) -> 0.019153236
A5: AUD | B5: Australian Dollar | C5: 0.92666376 | D5: 1.0791401 | E5: AUD | F5: Australian Dollar | G5: =1/INDEX(C:C,MATCH(E5,A:A,0)) -> 1.0791401
A6: CAD | B6: Canadian Dollar | C6: 0.82948054 | D6: 1.2055738 | E6: CAD | F6: Canadian Dollar | G6: =1/INDEX(C:C,MATCH(E6,A:A,0)) -> 1.2055738
A7: SGD | B7: Singapore Dollar | C7: 0.77478879 | D7: 1.2906743 | E7: SGD | F7: Singapore Dollar | G7: =1/INDEX(C:C,MATCH(E7,A:A,0)) -> 1.2906743
A8: CHF | B8: Swiss Franc | C8: 0.48353014 | D8: 2.0681234 | E8: CHF | F8: Swiss Franc | G8: =1/INDEX(C:C,MATCH(E8,A:A,0)) -> 2.0681234
A9: MYR | B9: Malaysian Ringgit | C9: 2.5656351 | D9: 0.38976705 | E9: MYR | F9: Malaysian Ringgit | G9: =1/INDEX(C:C,MATCH(E9,A:A,0)) -> 0.38976705
A10: JPY | B10: Japanese Yen | C10: 87.804376 | D10: 0.011388954 | E10: JPY | F10: Japanese Yen | G10: =1/INDEX(C:C,MATCH(E10,A:A,0)) -> 0.011388954
A11: CNY | B11: Chinese Yuan Renminbi | C11: 4.3628898 | D11: 0.22920588 | E11: CNY | F11: Chinese Yuan Renminbi | G11: =1/INDEX(C:C,MATCH(E11,A:A,0)) -> 0.22920588
A12: NZD | B12: New Zealand Dollar | C12: 1 | D12: 1 | E12: NZD | F12: New Zealand Dollar | G12: =1/INDEX(C:C,MATCH(E12,A:A,0)) -> 1
... A162: TVD | B162: Tuvaluan Dollar | C162: 0.92666376 | D162: 1.0791401 | E162: TMT | F162: Guernsey Pound | G162: =1/INDEX(C:C,MATCH(E162,A:A,0)) -> 0.46793021
A163: ZMW | B163: Zambian Kwacha | C163: 14.597657 | D163: 0.068504144 | E163: TVD | G163: =1/INDEX(C:C,MATCH(E163,A:A,0)) -> 1.0791401
A164: ADA | B164: Cardano | C164: 1.0160711 | D164: 0.98418306 | E164: IMP | G164: =1/INDEX(C:C,MATCH(E164,A:A,0)) -> 2.2530079
A165: BCH | B165: Bitcoin Cash | C165: 0.0011852593 | D165: 843.69722 | E165: GGP | G165: =1/INDEX(C:C,MATCH(E165,A:A,0)) -> 2.2530079
A166: BTC | B166: Bitcoin | C166: 5.6554899e-06 | D166: 176819.34 | E166: ZMW | G166: =1/INDEX(C:C,MATCH(E166,A:A,0)) -> 0.068504144
A167: CLF | B167: CLF | C167: 0.014771204 | D167: 67.699288 | E167: BCH | G167: =1/INDEX(C:C,MATCH(E167,A:A,0)) -> 843.69722
A168: CNH | B168: Chinese Yuan Renminbi Offshore | C168: 4.3606347 | D168: 0.22932441 | E168: CLF | G168: =1/INDEX(C:C,MATCH(E168,A:A,0)) -> 67.699288
A169: DOGE | B169: Dogecoin | C169: 3.6896245 | D169: 0.27103029 | E169: CNH | G169: =1/INDEX(C:C,MATCH(E169,A:A,0)) -> 0.22932441
A170: DOT | B170: Polkadot | C170: 0.17920767 | D170: 5.5801184 | E170: ETH | G170: =1/INDEX(C:C,MATCH(E170,A:A,0)) -> 4066.7663
A171: ETH | B171: Ethereum | C171: 0.00024589562 | D171: 4066.7663 | E171: LINK | G171: =1/INDEX(C:C,MATCH(E171,A:A,0)) -> 21.980528
A172: EURC | B172: EURC | C172: 0.51848771 | D172: 1.928686 | E172: LTC | G172: =1/INDEX(C:C,MATCH(E172,A:A,0)) -> 141.23046
A173: LINK | B173: Chainlink | C173: 0.045494813 | D173: 21.980528 | E173: MXV | G173: =1/INDEX(C:C,MATCH(E173,A:A,0)) -> 0.74089293
A174: LTC | B174: Litecoin | C174: 0.0070806255 | D174: 141.23046 | E174: XBT | G174: =1/INDEX(C:C,MATCH(E174,A:A,0)) -> 176819.34
... A181: USDP | B181: USDP | C181: 0.60911126 | D181: 1.6417362 | E181: DOT | G181: =1/INDEX(C:C,MATCH(E181,A:A,0)) -> 5.5801184
A182: VED | B182: VED | C182: 64.850303 | D182: 0.015420129
A183: XBT | B183: XBT | C183: 5.6554899e-06 | D183: 176819.34
A184: XCG | B184: Caribbean Guilder | C184: 1.0970888 | D184: 0.91150321
A185: XLM | B185: Stellar Lumen | C185: 2.585882 | D185: 0.38671525
A186: XRP | B186: Ripple | C186: 0.27757599 | D186: 3.602617
A187: ZWG | B187: Zimbabwean Dollar | C187: 16.413995 | D187: 0.060923622

Sheet Streams
A1: StreamID | B1: StreamName
A2: S1 | B2: Peas
A3: S2 | B3: Dehulled peas
A4: S3 | B4: Hulls
A5: S4 | B5: Dehulled pea flour
A6: S5 | B6: NaOH solution
A7: S6 | B7: Water 1
A8: S7 | B8: Heat treated slurry
A9: S8 | B9: Cooled slurry
A10: S9 | B10: Sludge
A11: S10 | B11: Supernatant 1
A12: S11 | B12: Sediment 1
... A34: S33 | B34: Water vapour 2

Sheet SystemStreams
A1: StreamName | B1: StreamID | C1: Role | D1: Input/Output | E1: Price model | Q1: No. | R1: Stream type | S1: Input/Output | U1: No. | V1: Cost model description | W1: cost model name
A2: Peas | B2: =IF(A2="","",IFERROR(INDEX(Streams!$A:$A, MATCH(A2, Streams!$B:$B, 0)), "enter the stream name")) -> S1 | C2: Feedstock | D2: =IF(C2="","",IFERROR(INDEX($S:$S, MATCH(C2, $R:$R, 0)), "enter input or output")) -> Input | E2: static | Q2: 1 | R2: Feedstock | S2: Input | U2: 1 | V2: TBD | W2: static
A3: Hulls | B3: =IF(A3="","",IFERROR(INDEX(Streams!$A:$A, MATCH(A3, Streams!$B:$B, 0)), "enter the stream name")) -> S3 | C3: Byproduct | D3: =IF(C3="","",IFERROR(INDEX($S:$S, MATCH(C3, $R:$R, 0)), "enter input or output")) -> Output | E3: static | Q3: 2 | R3: Water | S3: Input | U3: 2 | V3: TBD | W3: linear_protein
A4: NaOH solution | B4: =IF(A4="","",IFERROR(INDEX(Streams!$A:$A, MATCH(A4, Streams!$B:$B, 0)), "enter the stream name")) -> S5 | C4: Solvent | D4: =IF(C4="","",IFERROR(INDEX($S:$S, MATCH(C4, $R:$R, 0)), "enter input or output")) -> Input | E4: static | Q4: 3 | R4: Solvent | S4: Input | U4: 3 | V4: TBD | W4: performance_index
A5: Water 1 | B5: =IF(A5="","",IFERROR(INDEX(Streams!$A:$A, MATCH(A5, Streams!$B:$B, 0)), "enter the stream name")) -> S6 | C5: Water | D5: =IF(C5="","",IFERROR(INDEX($S:$S, MATCH(C5, $R:$R, 0)), "enter input or output")) -> Input | E5: static | Q5: 4 | R5: Waste | S5: Output | U5: 4 | V5: TBD | W5: yield_adjusted
A6: Water 2 | B6: =IF(A6="","",IFERROR(INDEX(Streams!$A:$A, MATCH(A6, Streams!$B:$B, 0)), "enter the stream name")) -> S13 | C6: Water | D6: =IF(C6="","",IFERROR(INDEX($S:$S, MATCH(C6, $R:$R, 0)), "enter input or output")) -> Input | E6: static | Q6: 5 | R6: Product | S6: Output
A7: Whey 1 | B7: =IF(A7="","",IFERROR(INDEX(Streams!$A:$A, MATCH(A7, Streams!$B:$B, 0)), "enter the stream name")) -> S12 | C7: Waste | D7: =IF(C7="","",IFERROR(INDEX($S:$S, MATCH(C7, $R:$R, 0)), "enter input or output")) -> Output | E7: static | Q7: 6 | R7: Byproduct | S7: Output
A8: Whey 2 | B8: =IF(A8="","",IFERROR(INDEX(Streams!$A:$A, MATCH(A8, Streams!$B:$B, 0)), "enter the stream name")) -> S16 | C8: Waste | D8: =IF(C8="","",IFERROR(INDEX($S:$S, MATCH(C8, $R:$R, 0)), "enter input or output")) -> Output | E8: static
A9: Water 3 | B9: =IF(A9="","",IFERROR(INDEX(Streams!$A:$A, MATCH(A9, Streams!$B:$B, 0)), "enter the stream name")) -> S17 | C9: Water | D9: =IF(C9="","",IFERROR(INDEX($S:$S, MATCH(C9, $R:$R, 0)), "enter input or output")) -> Input | E9: static
A10: Dried sediment | B10: =IF(A10="","",IFERROR(INDEX(Streams!$A:$A, MATCH(A10, Streams!$B:$B, 0)), "enter the stream name")) -> S21 | C10: Byproduct | D10: =IF(C10="","",IFERROR(INDEX($S:$S, MATCH(C10, $R:$R, 0)), "enter input or output")) -> Output | E10: static
A11: Water vapour 1 | B11: =IF(A11="","",IFERROR(INDEX(Streams!$A:$A, MATCH(A11, Streams!$B:$B, 0)), "enter the stream name")) -> S22 | C11: Waste | D11: =IF(C11="","",IFERROR(INDEX($S:$S, MATCH(C11, $R:$R, 0)), "enter input or output")) -> Output | E11: static
A12: Water 4 | B12: =IF(A12="","",IFERROR(INDEX(Streams!$A:$A, MATCH(A12, Streams!$B:$B, 0)), "enter the stream name")) -> S25 | C12: Water | D12: =IF(C12="","",IFERROR(INDEX($S:$S, MATCH(C12, $R:$R, 0)), "enter input or output")) -> Input | E12: static
A13: Permeate 1 | B13: =IF(A13="","",IFERROR(INDEX(Streams!$A:$A, MATCH(A13, Streams!$B:$B, 0)), "enter the stream name")) -> S24 | C13: Waste | D13: =IF(C13="","",IFERROR(INDEX($S:$S, MATCH(C13, $R:$R, 0)), "enter input or output")) -> Output | E13: static
A14: Permeate 2 | B14: =IF(A14="","",IFERROR(INDEX(Streams!$A:$A, MATCH(A14, Streams!$B:$B, 0)), "enter the stream name")) -> S27 | C14: Waste | D14: =IF(C14="","",IFERROR(INDEX($S:$S, MATCH(C14, $R:$R, 0)), "enter input or output")) -> Output | E14: static
A15: Permeate 3 | B15: =IF(A15="","",IFERROR(INDEX(Streams!$A:$A, MATCH(A15, Streams!$B:$B, 0)), "enter the stream name")) -> S31 | C15: Waste | D15: =IF(C15="","",IFERROR(INDEX($S:$S, MATCH(C15, $R:$R, 0)), "enter input or output")) -> Output | E15: static
A16: Spray dried powder | B16: =IF(A16="","",IFERROR(INDEX(Streams!$A:$A, MATCH(A16, Streams!$B:$B, 0)), "enter the stream name")) -> S32 | C16: Product | D16: =IF(C16="","",IFERROR(INDEX($S:$S, MATCH(C16, $R:$R, 0)), "enter input or output")) -> Output | E16: linear_protein
A17: Water vapour 2 | B17: =IF(A17="","",IFERROR(INDEX(Streams!$A:$A, MATCH(A17, Streams!$B:$B, 0)), "enter the stream name")) -> S33 | C17: Waste | D17: =IF(C17="","",IFERROR(INDEX($S:$S, MATCH(C17, $R:$R, 0)), "enter input or output")) -> Output | E17: static
B18: =IF(A18="","",IFERROR(INDEX(Streams!$A:$A, MATCH(A18, Streams!$B:$B, 0)), "enter the stream name")) | D18: =IF(C18="","",IFERROR(INDEX($S:$S, MATCH(C18, $R:$R, 0)), "enter input or output"))
B19: =IF(A19="","",IFERROR(INDEX(Streams!$A:$A, MATCH(A19, Streams!$B:$B, 0)), "enter the stream name")) | D19: =IF(C19="","",IFERROR(INDEX($S:$S, MATCH(C19, $R:$R, 0)), "enter input or output"))
B20: =IF(A20="","",IFERROR(INDEX(Streams!$A:$A, MATCH(A20, Streams!$B:$B, 0)), "enter the stream name")) | D20: =IF(C20="","",IFERROR(INDEX($S:$S, MATCH(C20, $R:$R, 0)), "enter input or output"))
B21: =IF(A21="","",IFERROR(INDEX(Streams!$A:$A, MATCH(A21, Streams!$B:$B, 0)), "enter the stream name")) | D21: =IF(C21="","",IFERROR(INDEX($S:$S, MATCH(C21, $R:$R, 0)), "enter input or output"))
B22: =IF(A22="","",IFERROR(INDEX(Streams!$A:$A, MATCH(A22, Streams!$B:$B, 0)), "enter the stream name")) | D22: =IF(C22="","",IFERROR(INDEX($S:$S, MATCH(C22, $R:$R, 0)), "enter input or output"))
B23: =IF(A23="","",IFERROR(INDEX(Streams!$A:$A, MATCH(A23, Streams!$B:$B, 0)), "enter the stream name")) | D23: =IF(C23="","",IFERROR(INDEX($S:$S, MATCH(C23, $R:$R, 0)), "enter input or output"))
B24: =IF(A24="","",IFERROR(INDEX(Streams!$A:$A, MATCH(A24, Streams!$B:$B, 0)), "enter the stream name")) | D24: =IF(C24="","",IFERROR(INDEX($S:$S, MATCH(C24, $R:$R, 0)), "enter input or output"))
B25: =IF(A25="","",IFERROR(INDEX(Streams!$A:$A, MATCH(A25, Streams!$B:$B, 0)), "enter the stream name")) | D25: =IF(C25="","",IFERROR(INDEX($S:$S, MATCH(C25, $R:$R, 0)), "enter input or output"))
B26: =IF(A26="","",IFERROR(INDEX(Streams!$A:$A, MATCH(A26, Streams!$B:$B, 0)), "enter the stream name")) | D26: =IF(C26="","",IFERROR(INDEX($S:$S, MATCH(C26, $R:$R, 0)), "enter input or output"))
B27: =IF(A27="","",IFERROR(INDEX(Streams!$A:$A, MATCH(A27, Streams!$B:$B, 0)), "enter the stream name")) | D27: =IF(C27="","",IFERROR(INDEX($S:$S, MATCH(C27, $R:$R, 0)), "enter input or output"))
B28: =IF(A28="","",IFERROR(INDEX(Streams!$A:$A, MATCH(A28, Streams!$B:$B, 0)), "enter the stream name")) | D28: =IF(C28="","",IFERROR(INDEX($S:$S, MATCH(C28, $R:$R, 0)), "enter input or output"))
B29: =IF(A29="","",IFERROR(INDEX(Streams!$A:$A, MATCH(A29, Streams!$B:$B, 0)), "enter the stream name")) | D29: =IF(C29="","",IFERROR(INDEX($S:$S, MATCH(C29, $R:$R, 0)), "enter input or output"))
... B101: =IF(A101="","",IFERROR(INDEX(Streams!$A:$A, MATCH(A101, Streams!$B:$B, 0)), "enter the stream name")) | D101: =IF(C101="","",IFERROR(INDEX($S:$S, MATCH(C101, $R:$R, 0)), "enter input or output"))

Sheet Components
A1: StreamName | B1: StreamID | C1: Component | D1: Category | E1: Unit | O1: No. | P1: Tiers_of_components
A2: Peas | B2: =IF(A2="","",IFERROR(INDEX(Streams!$A:$A, MATCH(A2, Streams!$B:$B, 0)), "enter the stream name")) -> S1 | C2: Total mass | D2: Total | E2: kg | O2: 1 | P2: Total
A3: Peas | B3: =IF(A3="","",IFERROR(INDEX(Streams!$A:$A, MATCH(A3, Streams!$B:$B, 0)), "enter the stream name")) -> S1 | C3: Total Solids | D3: Solids | E3: kg | O3: 2 | P3: Solids
A4: Peas | B4: =IF(A4="","",IFERROR(INDEX(Streams!$A:$A, MATCH(A4, Streams!$B:$B, 0)), "enter the stream name")) -> S1 | C4: Ash | D4: Component | E4: kg | O4: 3 | P4: Component
A5: Peas | B5: =IF(A5="","",IFERROR(INDEX(Streams!$A:$A, MATCH(A5, Streams!$B:$B, 0)), "enter the stream name")) -> S1 | C5: Protein | D5: Component | E5: kg | O5: 4 | P5: Moisture
A6: Peas | B6: =IF(A6="","",IFERROR(INDEX(Streams!$A:$A, MATCH(A6, Streams!$B:$B, 0)), "enter the stream name")) -> S1 | C6: Fat | D6: Component | E6: kg
A7: Peas | B7: =IF(A7="","",IFERROR(INDEX(Streams!$A:$A, MATCH(A7, Streams!$B:$B, 0)), "enter the stream name")) -> S1 | C7: Starch | D7: Component | E7: kg
A8: Peas | B8: =IF(A8="","",IFERROR(INDEX(Streams!$A:$A, MATCH(A8, Streams!$B:$B, 0)), "enter the stream name")) -> S1 | C8: Sugars | D8: Component | E8: kg
A9: Peas | B9: =IF(A9="","",IFERROR(INDEX(Streams!$A:$A, MATCH(A9, Streams!$B:$B, 0)), "enter the stream name")) -> S1 | C9: Fibre | D9: Component | E9: kg
A10: Peas | B10: =IF(A10="","",IFERROR(INDEX(Streams!$A:$A, MATCH(A10, Streams!$B:$B, 0)), "enter the stream name")) -> S1 | C10: Other | D10: Component | E10: kg
A11: Peas | B11: =IF(A11="","",IFERROR(INDEX(Streams!$A:$A, MATCH(A11, Streams!$B:$B, 0)), "enter the stream name")) -> S1 | C11: Water | D11: Moisture | E11: kg
A12: NaOH solution | B12: =IF(A12="","",IFERROR(INDEX(Streams!$A:$A, MATCH(A12, Streams!$B:$B, 0)), "enter the stream name")) -> S5 | C12: Total mass | D12: Total | E12: kg
A13: NaOH solution | B13: =IF(A13="","",IFERROR(INDEX(Streams!$A:$A, MATCH(A13, Streams!$B:$B, 0)), "enter the stream name")) -> S5 | C13: Total Solids | D13: Solids | E13: kg
A14: NaOH solution | B14: =IF(A14="","",IFERROR(INDEX(Streams!$A:$A, MATCH(A14, Streams!$B:$B, 0)), "enter the stream name")) -> S5 | C14: NaOH | D14: Component | E14: kg
A15: NaOH solution | B15: =IF(A15="","",IFERROR(INDEX(Streams!$A:$A, MATCH(A15, Streams!$B:$B, 0)), "enter the stream name")) -> S5 | C15: Water | D15: Moisture | E15: kg
A16: Water 1 | B16: =IF(A16="","",IFERROR(INDEX(Streams!$A:$A, MATCH(A16, Streams!$B:$B, 0)), "enter the stream name")) -> S6 | C16: Total mass | D16: Total | E16: kg
A17: Water 1 | B17: =IF(A17="","",IFERROR(INDEX(Streams!$A:$A, MATCH(A17, Streams!$B:$B, 0)), "enter the stream name")) -> S6 | C17: Water | D17: Moisture | E17: kg
... A23: Water 4 | B23: =IF(A23="","",IFERROR(INDEX(Streams!$A:$A, MATCH(A23, Streams!$B:$B, 0)), "enter the stream name")) -> S25 | C23: Water | D23: Moisture | E23: kg

Sheet UnitOperations
A1: UnitID | B1: UnitName | C1: UnitClass | D1: PartitioningType | E1: Notes
A2: U1 | B2: Dehulling | C2: MyDehulling | D2: =IF(C2="","",IFERROR(INDEX(PythonUnitOps!$B$2:$B$98, MATCH(C2, PythonUnitOps!$A$2:$A$98, 0)), "enter the partitioning type")) -> Overall, Component
A3: U2 | B3: Milling | C3: MyImpactMilling | D3: =IF(C3="","",IFERROR(INDEX(PythonUnitOps!$B$2:$B$98, MATCH(C3, PythonUnitOps!$A$2:$A$98, 0)), "enter the partitioning type")) -> None
A4: U3 | B4: Wet extraction | C4: MyWetExtraction | D4: =IF(C4="","",IFERROR(INDEX(PythonUnitOps!$B$2:$B$98, MATCH(C4, PythonUnitOps!$A$2:$A$98, 0)), "enter the partitioning type")) -> None
A5: U4 | B5: Cooling | C5: MyCooling | D5: =IF(C5="","",IFERROR(INDEX(PythonUnitOps!$B$2:$B$98, MATCH(C5, PythonUnitOps!$A$2:$A$98, 0)), "enter the partitioning type")) -> None
A6: U5 | B6: Decanter centrifuge | C6: MyDecanterCentrifuge | D6: =IF(C6="","",IFERROR(INDEX(PythonUnitOps!$B$2:$B$98, MATCH(C6, PythonUnitOps!$A$2:$A$98, 0)), "enter the partitioning type")) -> Overall, Component
A7: U6 | B7: Clarification 1 | C7: MyClarifier | D7: =IF(C7="","",IFERROR(INDEX(PythonUnitOps!$B$2:$B$98, MATCH(C7, PythonUnitOps!$A$2:$A$98, 0)), "enter the partitioning type")) -> Overall, Component
A8: U7 | B8: Mixing 1 | C8: MyMixingTank | D8: =IF(C8="","",IFERROR(INDEX(PythonUnitOps!$B$2:$B$98, MATCH(C8, PythonUnitOps!$A$2:$A$98, 0)), "enter the partitioning type")) -> None
A9: U8 | B9: Clarification 2 | C9: MyClarifier | D9: =IF(C9="","",IFERROR(INDEX(PythonUnitOps!$B$2:$B$98, MATCH(C9, PythonUnitOps!$A$2:$A$98, 0)), "enter the partitioning type")) -> Overall, Component
A10: U9 | B10: Mixing 2 | C10: MyMixingTank | D10: =IF(C10="","",IFERROR(INDEX(PythonUnitOps!$B$2:$B$98, MATCH(C10, PythonUnitOps!$A$2:$A$98, 0)), "enter the partitioning type")) -> None
